// try{
//   throw new Error("My name is king")
// }
// catch(err){
//   console.log(err.name)
//   console.log(err.message)
//   console.log(err.stack)
// }

// const f = () => {
    try {
        let a = 0;
        console.log(program)
        // console.log("Program ran successfully")
        
}
catch (err) {
        // console.log("This is an error")
        console.log(p)
}
finally {
        console.log("I am a good boyuu")
        
}
 // console.log("I am a good boy")
// }

// f()
// console.log("End")